Workbook

Sheet Jugadores
A1: ID FotMob | B1: Jugador | C1: Club | D1: Conferencia | E1: Estado | F1: Línea | G1: Pos. principal | H1: Posiciones FotMob | I1: Dorsal | J1: Edad | K1: Nacimiento | L1: Nacionalidad | M1: Altura (cm) | N1: Valor est. FotMob (€) | O1: Lesionado | P1: PJ | Q1: Minutos | R1: Rating FotMob | S1: MVP partido | T1: Goles | U1: Goles de penal | V1: Asistencias | W1: G+A | X1: Goles /90 | Y1: Tiros /90 | Z1: Tiros a puerta /90 | AA1: Conversión tiro % | AB1: Ocasiones claras falladas | AC1: Ocasiones creadas | AD1: Ocasiones creadas /90 | AE1: Ocasiones claras creadas | AF1: Pases precisos /90 | AG1: Precisión pase % | AH1: Balones largos precisos /90 | AI1: Balón largo % | AJ1: Regates exitosos /90 | AK1: Regate % | AL1: Penales provocados | AM1: Faltas recibidas /90 | AN1: Acciones defensivas /90 | AO1: Entradas /90 | AP1: Intercepciones /90 | AQ1: Despejes /90 | AR1: Bloqueos /90 | AS1: Recuperaciones /90 | AT1: Recup. último tercio /90 | AU1: Recup. medio campo /90 | AV1: Faltas cometidas /90 | AW1: Amarillas | AX1: Rojas | AY1: Penales cometidos | AZ1: Porterías a cero | BA1: Atajadas /90 | BB1: % Atajadas | BC1: Goles recibidos /90 | BD1: Enlace FotMob
A2: 912343 | B2: Jassem Koleilat | C2: Birmingham Legion FC | D2: Eastern | E2: En plantilla | F2: Portero | G2: GK | H2: GK | I2: 1 | J2: 27 | K2: 1999-07-30 | L2: Czechia | M2: 188 | P2: 24 | Q2: 2144 | R2: 6.94 | S2: 1 | AF2: 14.9 | AG2: 63.7 | AJ2: 0.1 | AK2: 100 | AN2: 1 | AO2: 0 | AQ2: 1 | AS2: 6.8 | AW2: 2 | AZ2: 5 | BA2: 3.8 | BB2: 70.9 | BC2: 1.6 | BD2: https://www.fotmob.com/players/912343/jassem-koleilat
A3: 1804493 | B3: Trevor McMullen | C3: Birmingham Legion FC | D3: Eastern | E3: En plantilla | F3: Portero | G3: GK | H3: GK | I3: 12 | J3: 24 | K3: 2002-01-23 | L3: USA | M3: 185 | P3: 2 | Q3: 106 | BD3: https://www.fotmob.com/players/1804493/trevor-mcmullen
A4: 1368657 | B4: Dawson McCartney | C4: Birmingham Legion FC | D4: Eastern | E4: En plantilla | F4: Defensa | G4: LB | H4: LB | I4: 11 | J4: 27 | K4: 1998-10-15 | L4: USA | M4: 183 | P4: 23 | Q4: 1480 | R4: 6.76 | S4: 0 | V4: 5 | Y4: 0.3 | AA4: 0 | AC4: 19 | AD4: 1.2 | AE4: 3 | AF4: 38.4 | AG4: 82.4 | AH4: 1.6 | AI4: 36.1 | AJ4: 0.4 | AK4: 46.2 | AN4: 5.2 | AO4: 1.6 | AP4: 0.7 | AQ4: 2.7 | AR4: 0.3 | AS4: 4 | AT4: 0.2 | AU4: 1.8 | AV4: 0.6 | AW4: 1 | AY4: 1 | BD4: https://www.fotmob.com/players/1368657/dawson-mccartney
A5: 621906 | B5: Phanuel Kavita | C5: Birmingham Legion FC | D5: Eastern | E5: En plantilla | F5: Defensa | G5: CB | H5: CB | I5: 3 | J5: 33 | K5: 1993-03-09 | L5: Rwanda | M5: 188 | P5: 15 | Q5: 1176 | R5: 6.43 | S5: 0 | T5: 1 | U5: 0 | X5: 0.08 | Y5: 0.4 | Z5: 0.1 | AA5: 20 | AC5: 2 | AD5: 0.2 | AF5: 32.5 | AG5: 87.1 | AH5: 1.2 | AI5: 26.7 | AN5: 7.3 | AO5: 0.4 | AP5: 0.4 | AQ5: 5.4 | AR5: 1.1 | AS5: 1.8 | AT5: 0.1 | AU5: 0.4 | AV5: 0.7 | AW5: 2 | AY5: 1 | BD5: https://www.fotmob.com/players/621906/phanuel-kavita
A6: 1262891 | B6: Bryce Washington | C6: Birmingham Legion FC | D6: Eastern | E6: En plantilla | F6: Defensa | G6: CB | H6: CB | I6: 27 | J6: 28 | K6: 1998-09-12 | L6: USA | M6: 188 | N6: 50000 | P6: 15 | Q6: 1156 | R6: 6.47 | S6: 0 | Y6: 0.3 | AA6: 0 | AF6: 31.2 | AG6: 90.9 | AH6: 1 | AI6: 56.5 | AJ6: 0.2 | AK6: 100 | AN6: 11.1 | AO6: 0.8 | AP6: 1.1 | AQ6: 7.6 | AR6: 1.7 | AS6: 2.3 | AV6: 0.2 | AW6: 1 | BD6: https://www.fotmob.com/players/1262891/bryce-washington
A7: 1252148 | B7: Nico Brown | C7: Birmingham Legion FC | D7: Eastern | E7: En plantilla | F7: Defensa | G7: LB | H7: LB,RB,RM | I7: 77 | J7: 28 | K7: 1998-08-11 | L7: Jamaica | M7: 180 | N7: 184308 | P7: 16 | Q7: 1046 | R7: 6.56 | S7: 0 | T7: 1 | U7: 0 | X7: 0.09 | Y7: 0.4 | Z7: 0.1 | AA7: 20 | AC7: 8 | AD7: 0.7 | AE7: 3 | AF7: 31.9 | AG7: 85.9 | AH7: 0.8 | AI7: 31 | AJ7: 0.5 | AK7: 66.7 | AN7: 6.9 | AO7: 1.2 | AP7: 0.7 | AQ7: 4.7 | AR7: 0.3 | AS7: 2.9 | AV7: 0.9 | AW7: 1 | AX7: 1 | BD7: https://www.fotmob.com/players/1252148/nico-brown
A8: 1439803 | B8: Hamady Diop | C8: Birmingham Legion FC | D8: Eastern | E8: En plantilla | F8: Defensa | G8: CB | H8: CB | I8: 32 | J8: 24 | K8: 2001-12-26 | L8: Senegal | M8: 183 | N8: 118522 | P8: 14 | Q8: 982 | R8: 6.9 | S8: 0 | Y8: 0.4 | AA8: 0 | AC8: 5 | AD8: 0.5 | AF8: 59.8 | AG8: 85.6 | AH8: 5.4 | AI8: 51.3 | AJ8: 0.3 | AK8: 42.9 | AN8: 8.3 | AO8: 1.3 | AP8: 1.2 | AQ8: 4.9 | AR8: 1 | AS8: 3.8 | AT8: 0.1 | AU8: 0.7 | AV8: 1.5 | AW8: 1 | BD8: https://www.fotmob.com/players/1439803/hamady-diop
A9: 1624479 | B9: Amir Daley | C9: Birmingham Legion FC | D9: Eastern | E9: En plantilla | F9: Defensa | G9: RB | H9: RB,RWB,RM,LB | I9: 26 | J9: 24 | K9: 2002-02-26 | L9: Antigua and Barbuda | M9: 175 | P9: 15 | Q9: 775 | R9: 6.58 | S9: 0 | Y9: 0.6 | AA9: 0 | AC9: 5 | AD9: 0.6 | AF9: 28.5 | AG9: 80.6 | AH9: 0.7 | AI9: 35.3 | AJ9: 0.8 | AK9: 36.8 | AN9: 6.3 | AO9: 2.1 | AP9: 1.2 | AQ9: 2.7 | AR9: 0.3 | AS9: 3.4 | AV9: 1.2 | AW9: 1 | AY9: 1 | BD9: https://www.fotmob.com/players/1624479/amir-daley
A10: 1059682 | B10: AJ Paterson | C10: Birmingham Legion FC | D10: Eastern | E10: En plantilla | F10: Defensa | G10: CB | H10: CB | I10: 20 | J10: 30 | K10: 1996-01-31 | L10: Grenada | M10: 188 | P10: 5 | Q10: 220 | BD10: https://www.fotmob.com/players/1059682/aj-paterson
A11: 1682447 | B11: Seth Antwi | C11: Birmingham Legion FC | D11: Eastern | E11: En plantilla | F11: Mediocampista | G11: CDM | H11: CDM | I11: 18 | J11: 26 | K11: 1999-11-09 | L11: Ghana | M11: 175 | P11: 25 | Q11: 2244 | R11: 6.87 | S11: 0 | Y11: 0.1 | AA11: 0 | AC11: 9 | AD11: 0.4 | AF11: 44.7 | AG11: 91.4 | AH11: 0.8 | AI11: 34.5 | AJ11: 0.2 | AK11: 80 | AN11: 6.1 | AO11: 1.7 | AP11: 1 | AQ11: 3 | AR11: 0.4 | AS11: 4.2 | AT11: 0.2 | AU11: 2.2 | AV11: 1.4 | AW11: 8 | BD11: https://www.fotmob.com/players/1682447/seth-antwi
A12: 847603 | B12: Samuel Shashoua | C12: Birmingham Legion FC | D12: Eastern | E12: En plantilla | F12: Mediocampista | G12: CDM | H12: CDM,CAM | I12: 10 | J12: 27 | K12: 1999-05-13 | L12: England | M12: 176 | P12: 19 | Q12: 1431 | R12: 7.12 | S12: 1 | T12: 2 | U12: 0 | V12: 1 | X12: 0.13 | Y12: 2.3 | Z12: 0.4 | AA12: 5.4 | AB12: 2 | AC12: 36 | AD12: 2.3 | AE12: 1 | AF12: 66.2 | AG12: 89.3 | AH12: 5 | AI12: 67.5 | AJ12: 1.4 | AK12: 50 | AN12: 1.5 | AO12: 1.1 | AP12: 0.3 | AQ12: 0.1 | AS12: 5.2 | AT12: 0.7 | AU12: 2.3 | AV12: 0.6 | AW12: 1 | BD12: https://www.fotmob.com/players/847603/samuel-shashoua
A13: 530617 | B13: Tyler Pasher | C13: Birmingham Legion FC | D13: Eastern | E13: En plantilla | F13: Mediocampista | G13: CAM | H13: CAM,RW | I13: 15 | J13: 32 | K13: 1994-04-27 | L13: Canada | M13: 180 | P13: 20 | Q13: 1406 | R13: 6.97 | S13: 2 | T13: 5 | U13: 2 | V13: 2 | X13: 0.32 | Y13: 1.9 | Z13: 0.4 | AA13: 16.7 | AB13: 2 | AC13: 28 | AD13: 1.8 | AE13: 2 | AF13: 38.5 | AG13: 86.9 | AH13: 1.2 | AI13: 51.4 | AJ13: 1.2 | AK13: 54.3 | AN13: 1.1 | AO13: 0.7 | AP13: 0.3 | AQ13: 0.1 | AS13: 3.1 | AT13: 0.6 | AU13: 1.2 | AV13: 0.8 | BD13: https://www.fotmob.com/players/530617/tyler-pasher
A14: 932131 | B14: Peter-Lee Vassell | C14: Birmingham Legion FC | D14: Eastern | E14: En plantilla | F14: Mediocampista | G14: CAM | H14: CAM,RW,CM | I14: 16 | J14: 28 | K14: 1998-02-03 | L14: Jamaica | M14: 180 | P14: 21 | Q14: 1201 | R14: 6.86 | S14: 1 | T14: 2 | U14: 0 | V14: 4 | X14: 0.15 | Y14: 3 | Z14: 1 | AA14: 5 | AB14: 3 | AC14: 12 | AD14: 0.9 | AE14: 3 | AF14: 26.1 | AG14: 81.9 | AH14: 1.2 | AI14: 72.7 | AJ14: 1.2 | AK14: 61.5 | AL14: 1 | AM14: 1.3 | AN14: 2.5 | AO14: 1.1 | AP14: 0.5 | AQ14: 0.7 | AR14: 0.1 | AS14: 3.3 | AT14: 0.4 | AU14: 1.3 | AV14: 0.7 | AW14: 2 | BD14: https://www.fotmob.com/players/932131/peter-lee-vassell
A15: 860928 | B15: Samuel McIllhatton | C15: Birmingham Legion FC | D15: Eastern | E15: En plantilla | F15: Mediocampista | G15: CDM | H15: CDM,CM | I15: 6 | J15: 28 | K15: 1998-06-29 | L15: Australia | M15: 170 | P15: 19 | Q15: 940 | R15: 6.83 | S15: 1 | T15: 1 | U15: 0 | X15: 0.1 | Y15: 1.2 | Z15: 0.5 | AA15: 7.7 | AC15: 10 | AD15: 1 | AF15: 48.1 | AG15: 85.4 | AH15: 3.5 | AI15: 58.7 | AJ15: 1 | AK15: 62.5 | AN15: 7.1 | AO15: 2.4 | AP15: 2.3 | AQ15: 2 | AR15: 0.4 | AS15: 5.1 | AT15: 0.1 | AU15: 2.8 | AV15: 0.8 | AW15: 3 | BD15: https://www.fotmob.com/players/860928/samuel-mcillhatton
A16: 1431704 | B16: Kadeem Cole | C16: Birmingham Legion FC | D16: Eastern | E16: En plantilla | F16: Mediocampista | G16: CDM | H16: CDM,CM,CB | I16: 8 | J16: 27 | K16: 1999-05-12 | L16: Nicaragua | M16: 178 | P16: 12 | Q16: 668 | AC16: 3 | AD16: 0.4 | AE16: 1 | AW16: 2 | BD16: https://www.fotmob.com/players/1431704/kadeem-cole
A17: 1190660 | B17: Serge Ngoma | C17: Birmingham Legion FC | D17: Eastern | E17: En plantilla | F17: Mediocampista | G17: RW | H17: RW | I17: 81 | J17: 21 | K17: 2005-07-09 | L17: USA | M17: 178 | N17: 670583 | P17: 21 | Q17: 504 | R17: 6.55 | S17: 0 | T17: 2 | U17: 0 | V17: 2 | X17: 0.36 | Y17: 2.3 | Z17: 1.1 | AA17: 15.4 | AB17: 1 | AC17: 10 | AD17: 1.8 | AE17: 4 | AF17: 21.4 | AG17: 77.4 | AH17: 0.4 | AI17: 33.3 | AJ17: 1.8 | AK17: 50 | AN17: 4.1 | AO17: 2 | AQ17: 2 | AR17: 0.2 | AS17: 3.4 | AT17: 0.4 | AU17: 1.1 | AV17: 2.3 | AW17: 3 | BD17: https://www.fotmob.com/players/1190660/serge-ngoma
A18: 1637902 | B18: Gevork Diarbian | C18: Birmingham Legion FC | D18: Eastern | E18: En plantilla | F18: Delantero | G18: LW | H18: LW | I18: 19 | J18: 24 | K18: 2001-12-12 | L18: USA | M18: 170 | P18: 25 | Q18: 2005 | R18: 6.9 | S18: 2 | T18: 2 | U18: 0 | V18: 4 | X18: 0.09 | Y18: 2.1 | Z18: 0.8 | AA18: 4.3 | AB18: 6 | AC18: 34 | AD18: 1.5 | AE18: 8 | AF18: 20.2 | AG18: 83.8 | AH18: 0.4 | AI18: 57.1 | AJ18: 1.4 | AK18: 39 | AL18: 1 | AM18: 2.9 | AN18: 1.4 | AO18: 0.6 | AP18: 0.2 | AQ18: 0.5 | AR18: 0.1 | AS18: 3.1 | AT18: 0.5 | AU18: 1.3 | AV18: 1.3 | AW18: 5 | BD18: https://www.fotmob.com/players/1637902/gevork-diarbian
A19: 1662187 | B19: Sebastian Tregarthen | C19: Birmingham Legion FC | D19: Eastern | E19: En plantilla | F19: Delantero | G19: RW | H19: RW,RB | I19: 21 | J19: 26 | K19: 2000-07-05 | L19: Uruguay | M19: 170 | P19: 23 | Q19: 1754 | R19: 7.02 | S19: 2 | T19: 4 | U19: 0 | V19: 1 | X19: 0.21 | Y19: 1.7 | Z19: 0.6 | AA19: 11.8 | AB19: 2 | AC19: 16 | AD19: 0.8 | AE19: 3 | AF19: 21 | AG19: 71.8 | AH19: 0.8 | AI19: 22.9 | AJ19: 1.6 | AK19: 45.7 | AN19: 6.3 | AO19: 2 | AP19: 1.6 | AQ19: 2.3 | AR19: 0.4 | AS19: 3.7 | AT19: 0.1 | AU19: 1.6 | AV19: 1.3 | AW19: 3 | BD19: https://www.fotmob.com/players/1662187/sebastian-tregarthen
A20: 790332 | B20: Ronaldo Damus | C20: Birmingham Legion FC | D20: Eastern | E20: En plantilla | F20: Delantero | G20: ST | H20: ST | I20: 9 | J20: 27 | K20: 1999-09-12 | L20: Haiti | M20: 178 | P20: 22 | Q20: 1163 | R20: 6.56 | S20: 0 | T20: 6 | U20: 0 | X20: 0.46 | Y20: 3 | Z20: 1.2 | AA20: 15.4 | AB20: 11 | AC20: 13 | AD20: 1 | AE20: 2 | AF20: 7.2 | AG20: 78.2 | AH20: 0.2 | AI20: 60 | AJ20: 0.5 | AK20: 50 | AN20: 2.1 | AO20: 0.7 | AP20: 0.3 | AQ20: 1.1 | AS20: 1.6 | AT20: 0.3 | AU20: 0.9 | AV20: 1.5 | AW20: 3 | BD20: https://www.fotmob.com/players/790332/ronaldo-damus
A21: 621524 | B21: Romario Williams | C21: Birmingham Legion FC | D21: Eastern | E21: En plantilla | F21: Delantero | G21: ST | H21: ST | I21: 17 | J21: 32 | K21: 1994-08-15 | L21: Jamaica | M21: 185 | N21: 103832 | P21: 21 | Q21: 1068 | R21: 6.92 | S21: 0 | T21: 7 | U21: 0 | V21: 2 | X21: 0.59 | Y21: 2.3 | Z21: 0.8 | AA21: 25.9 | AB21: 2 | AC21: 16 | AD21: 1.3 | AE21: 3 | AF21: 12.7 | AG21: 75.5 | AH21: 0.4 | AI21: 62.5 | AJ21: 0.6 | AK21: 70 | AL21: 2 | AM21: 1.7 | AN21: 2.9 | AO21: 1.1 | AP21: 0.1 | AQ21: 1.7 | AS21: 1.9 | AT21: 0.3 | AU21: 1.2 | AV21: 2 | AW21: 6 | BD21: https://www.fotmob.com/players/621524/romario-williams
A22: 622027 | B22: Sebastián Saucedo | C22: Birmingham Legion FC | D22: Eastern | E22: En plantilla | F22: Delantero | G22: LW | H22: LW | I22: 7 | J22: 29 | K22: 1997-01-22 | L22: USA | M22: 170 | P22: 14 | Q22: 197 | T22: 2 | U22: 1 | V22: 1 | X22: 0.91 | Y22: 5 | Z22: 1.8 | AA22: 18.2 | AC22: 10 | AD22: 4.6 | AF22: 48.9 | AG22: 82.9 | AH22: 5.9 | AI22: 72.2 | AJ22: 0.9 | AK22: 22.2 | AL22: 1 | AM22: 5 | AN22: 1.4 | AO22: 0.5 | AP22: 0.5 | AQ22: 0.5 | AS22: 9.1 | AT22: 0.9 | AU22: 4.1 | AV22: 1.8 | AW22: 3 | BD22: https://www.fotmob.com/players/622027/sebastian-saucedo
A23: 1780513 | B23: Jonathan Hernandez | C23: Birmingham Legion FC | D23: Eastern | E23: En plantilla | F23: Delantero | I23: 30 | J23: 18 | K23: 2008-06-07 | L23: USA | M23: 180 | BD23: https://www.fotmob.com/players/1780513/jonathan-hernandez
A24: 1781517 | B24: Jaylen Lester | C24: Birmingham Legion FC | D24: Eastern | E24: En plantilla | F24: Delantero | I24: 34 | J24: 18 | K24: 2008-04-30 | L24: Jamaica | M24: 178 | BD24: https://www.fotmob.com/players/1781517/jaylen-lester
A25: 1171002 | B25: Lukas Burns | C25: Brooklyn | D25: Eastern | E25: En plantilla | F25: Portero | G25: GK | H25: GK | I25: 30 | J25: 24 | K25: 2002-05-14 | L25: USA | M25: 196 | P25: 12 | Q25: 1035 | AZ25: 1 | BD25: https://www.fotmob.com/players/1171002/lukas-burns
A26: 928437 | B26: Jackson Lee | C26: Brooklyn | D26: Eastern | E26: En plantilla | F26: Portero | G26: GK | H26: GK | I26: 1 | J26: 25 | K26: 2001-09-10 | L26: Australia | M26: 191 | N26: 65115 | P26: 11 | Q26: 930 | AW26: 2 | AZ26: 1 | BD26: https://www.fotmob.com/players/928437/jackson-lee
A27: 936220 | B27: Thomas Vancaeyezeele | C27: Brooklyn | D27: Eastern | E27: En plantilla | F27: Defensa | G27: CB | H27: CB,RB,CDM | I27: 92 | J27: 32 | K27: 1994-07-27 | L27: French Guiana | M27: 180 | N27: 50000 | P27: 23 | Q27: 1930 | R27: 6.61 | S27: 0 | V27: 2 | Y27: 0.6 | Z27: 0.1 | AA27: 0 | AB27: 1 | AC27: 14 | AD27: 0.7 | AE27: 1 | AF27: 35.5 | AG27: 76.9 | AH27: 2.5 | AI27: 36.2 | AJ27: 0.2 | AK27: 23.5 | AN27: 7.6 | AO27: 2.1 | AP27: 1.4 | AQ27: 3.5 | AR27: 0.7 | AS27: 4.1 | AT27: 0.3 | AU27: 1.6 | AV27: 0.9 | AW27: 2 | BD27: https://www.fotmob.com/players/936220/thomas-vancaeyezeele
A28: 1447526 | B28: Gabriel Alves | C28: Brooklyn | D28: Eastern | E28: En plantilla | F28: Defensa | G28: LB | H28: LB,CB | I28: 3 | J28: 27 | K28: 1999-02-10 | L28: Brazil | M28: 185 | N28: 126237 | P28: 23 | Q28: 1838 | R28: 6.41 | S28: 0 | Y28: 0.4 | Z28: 0.1 | AA28: 0 | AC28: 9 | AD28: 0.4 | AE28: 1 | AF28: 31.1 | AG28: 77.2 | AH28: 2.4 | AI28: 39.5 | AJ28: 0.2 | AK28: 66.7 | AN28: 7.5 | AO28: 1.5 | AP28: 1.2 | AQ28: 4.4 | AR28: 0.5 | AS28: 3.5 | AT28: 0.1 | AU28: 1.1 | AV28: 1.6 | AW28: 5 | AX28: 2 | AY28: 1 | BD28: https://www.fotmob.com/players/1447526/gabriel-alves
A29: 1248123 | B29: Vuk Latinovich | C29: Brooklyn | D29: Eastern | E29: En plantilla | F29: Defensa | G29: CB | H29: CB | I29: 6 | J29: 29 | K29: 1997-09-14 | L29: Serbia | M29: 186 | N29: 50000 | P29: 21 | Q29: 1673 | R29: 6.67 | S29: 0 | Y29: 0.5 | Z29: 0.2 | AA29: 0 | AC29: 9 | AD29: 0.5 | AE29: 2 | AF29: 41.7 | AG29: 80.2 | AH29: 3.9 | AI29: 44.5 | AJ29: 0.1 | AK29: 100 | AN29: 11.4 | AO29: 1.3 | AP29: 1.7 | AQ29: 7.7 | AR29: 0.6 | AS29: 3.2 | AV29: 1.2 | AW29: 6 | BD29: https://www.fotmob.com/players/1248123/vuk-latinovich
A30: 1935110 | B30: Callum Frogson | C30: Brooklyn | D30: Eastern | E30: En plantilla | F30: Defensa | G30: CB | H30: CB,RB,LB | I30: 24 | J30: 22 | K30: 2003-10-11 | L30: England | M30: 188 | N30: 119504 | P30: 18 | Q30: 1260 | R30: 6.69 | S30: 0 | Y30: 0.4 | Z30: 0.2 | AA30: 0 | AB30: 1 | AC30: 3 | AD30: 0.2 | AF30: 29.8 | AG30: 81.4 | AH30: 1.1 | AI30: 32 | AN30: 10.6 | AO30: 2.1 | AP30: 2.1 | AQ30: 5.6 | AR30: 0.7 | AS30: 3.5 | AT30: 0.1 | AU30: 1.6 | AV30: 1.6 | AW30: 4 | AY30: 1 | BD30: https://www.fotmob.com/players/1935110/callum-frogson
A31: 388894 | B31: Ryan McLaughlin | C31: Brooklyn | D31: Eastern | E31: En plantilla | F31: Defensa | G31: RB | H31: RB,RM | I31: 23 | J31: 32 | K31: 1994-09-30 | L31: Northern Ireland | M31: 175 | N31: 50000 | P31: 18 | Q31: 1118 | R31: 6.72 | S31: 0 | Y31: 0.2 | AA31: 0 | AC31: 5 | AD31: 0.4 | AF31: 28.5 | AG31: 77 | AH31: 2.5 | AI31: 43.7 | AJ31: 0.5 | AK31: 50 | AN31: 7.5 | AO31: 2.4 | AP31: 1.1 | AQ31: 3.5 | AR31: 0.4 | AS31: 4.1 | AT31: 0.2 | AU31: 2 | AV31: 1 | AW31: 1 | BD31: https://www.fotmob.com/players/388894/ryan-mclaughlin
A32: 1024286 | B32: Rocco Romeo | C32: Brooklyn | D32: Eastern | E32: En plantilla | F32: Defensa | G32: CB | H32: CB | I32: 4 | J32: 26 | K32: 2000-03-25 | L32: Canada | M32: 196 | N32: 55715 | P32: 14 | Q32: 783 | R32: 6.34 | S32: 0 | Y32: 0.2 | AA32: 0 | AB32: 1 | AC32: 3 | AD32: 0.3 | AF32: 37.8 | AG32: 78.5 | AH32: 4.7 | AI32: 46.1 | AN32: 9.5 | AO32: 1.1 | AP32: 1 | AQ32: 6.6 | AR32: 0.8 | AS32: 2.9 | AV32: 1 | AW32: 2 | BD32: https://www.fotmob.com/players/1024286/rocco-romeo
A33: 1138224 | B33: So Nishikawa | C33: Brooklyn | D33: Eastern | E33: En plantilla | F33: Defensa | G33: LB | H33: LB | I33: 13 | J33: 25 | K33: 2001-06-18 | L33: Japan | M33: 178 | N33: 50000 | P33: 13 | Q33: 411 | V33: 1 | Y33: 1.1 | Z33: 0.2 | AA33: 0 | AC33: 6 | AD33: 1.3 | AE33: 2 | AF33: 35.7 | AG33: 74.8 | AH33: 2.6 | AI33: 33.3 | AJ33: 2.2 | AK33: 71.4 | AN33: 8.3 | AO33: 0.9 | AP33: 1.5 | AQ33: 5.7 | AR33: 0.2 | AS33: 6.1 | AT33: 0.2 | AU33: 3.3 | AV33: 0.9 | AW33: 2 | BD33: https://www.fotmob.com/players/1138224/so-nishikawa
A34: 1724754 | B34: Taimu Okiyoshi | C34: Brooklyn | D34: Eastern | E34: En plantilla | F34: Mediocampista | G34: CDM | H34: CDM,CM | I34: 86 | J34: 25 | K34: 2001-09-05 | L34: Japan | M34: 175 | N34: 99198 | P34: 21 | Q34: 1624 | R34: 6.6 | S34: 0 | Y34: 0.3 | Z34: 0.2 | AA34: 0 | AC34: 7 | AD34: 0.4 | AF34: 30.1 | AG34: 77.6 | AH34: 1.9 | AI34: 37 | AJ34: 0.4 | AK34: 57.1 | AN34: 4.5 | AO34: 1.6 | AP34: 1 | AQ34: 1.7 | AR34: 0.2 | AS34: 4.9 | AT34: 0.6 | AU34: 2.4 | AV34: 0.9 | AW34: 2 | BD34: https://www.fotmob.com/players/1724754/taimu-okiyoshi
A35: 526485 | B35: Tommy McNamara | C35: Brooklyn | D35: Eastern | E35: En plantilla | F35: Mediocampista | G35: CDM | H35: CDM,CAM,CM | I35: 7 | J35: 35 | K35: 1991-02-06 | L35: USA | M35: 185 | N35: 50000 | P35: 23 | Q35: 1391 | R35: 6.56 | S35: 1 | T35: 2 | U35: 2 | V35: 1 | X35: 0.13 | Y35: 0.8 | Z35: 0.3 | AA35: 15.4 | AC35: 16 | AD35: 1 | AE35: 2 | AF35: 40.8 | AG35: 85.9 | AH35: 2.3 | AI35: 55.4 | AJ35: 0.3 | AK35: 50 | AL35: 1 | AM35: 1.6 | AN35: 3.8 | AO35: 1.5 | AP35: 0.8 | AQ35: 1.3 | AR35: 0.2 | AS35: 3.2 | AT35: 0.3 | AU35: 1.8 | AV35: 0.9 | AW35: 4 | AX35: 1 | BD35: https://www.fotmob.com/players/526485/tommy-mcnamara
A36: 1440048 | B36: Malik Pinto | C36: Brooklyn | D36: Eastern | E36: En plantilla | F36: Mediocampista | G36: CDM | H36: CDM,RB,CM | I36: 5 | J36: 24 | K36: 2002-08-09 | L36: USA | M36: 180 | N36: 68062 | P36: 19 | Q36: 1098 | R36: 6.14 | S36: 0 | Y36: 0.6 | Z36: 0.2 | AA36: 0 | AC36: 5 | AD36: 0.4 | AF36: 27.5 | AG36: 78 | AH36: 1.5 | AI36: 40 | AJ36: 0.1 | AK36: 16.7 | AN36: 5.9 | AO36: 2.3 | AP36: 1.1 | AQ36: 2 | AR36: 0.5 | AS36: 3.2 | AT36: 0.2 | AU36: 1.6 | AV36: 1.5 | AW36: 2 | AY36: 1 | BD36: https://www.fotmob.com/players/1440048/malik-pinto
A37: 1170973 | B37: Jaden Servania | C37: Brooklyn | D37: Eastern | E37: En plantilla | F37: Mediocampista | G37: CAM | H37: CAM,RW,LW | I37: 11 | J37: 25 | K37: 2001-07-16 | L37: Puerto Rico | M37: 183 | N37: 78213 | P37: 20 | Q37: 955 | R37: 6.43 | S37: 0 | T37: 1 | U37: 0 | X37: 0.09 | Y37: 0.9 | Z37: 0.3 | AA37: 10 | AC37: 12 | AD37: 1.1 | AF37: 17.4 | AG37: 72.8 | AH37: 1.1 | AI37: 40 | AJ37: 1.5 | AK37: 51.6 | AN37: 2 | AO37: 0.7 | AP37: 0.4 | AQ37: 0.8 | AR37: 0.1 | AS37: 3 | AT37: 0.4 | AU37: 1.7 | AV37: 2.1 | AW37: 4 | BD37: https://www.fotmob.com/players/1170973/jaden-servania
A38: 1639626 | B38: Peter Mangione | C38: Brooklyn | D38: Eastern | E38: En plantilla | F38: Mediocampista | G38: CAM | H38: CAM,CDM,RB,ST | I38: 27 | J38: 25 | K38: 2001-08-25 | L38: USA | M38: 180 | N38: 75435 | P38: 21 | Q38: 756 | R38: 6.43 | S38: 1 | T38: 3 | U38: 0 | X38: 0.36 | Y38: 2.3 | Z38: 1.1 | AA38: 15.8 | AB38: 2 | AC38: 6 | AD38: 0.7 | AF38: 19 | AG38: 75.8 | AH38: 1.2 | AI38: 62.5 | AJ38: 0.6 | AK38: 33.3 | AL38: 1 | AM38: 1.2 | AN38: 2.1 | AO38: 0.8 | AP38: 0.2 | AQ38: 1 | AR38: 0.1 | AS38: 2.5 | AT38: 0.2 | AU38: 1.5 | AV38: 1.9 | BD38: https://www.fotmob.com/players/1639626/peter-mangione
A39: 1460074 | B39: John Klein | C39: Brooklyn | D39: Eastern | E39: En plantilla | F39: Mediocampista | G39: LM | H39: LM,CDM | I39: 8 | J39: 26 | K39: 1999-11-07 | L39: USA | M39: 170 | N39: 76984 | P39: 9 | Q39: 260 | AC39: 2 | AD39: 0.7 | AE39: 1 | AW39: 1 | BD39: https://www.fotmob.com/players/1460074/john-klein
A40: 924483 | B40: Anthony Fontana | C40: Brooklyn | D40: Eastern | E40: En plantilla | F40: Mediocampista | G40: CAM | H40: CAM | I40: 21 | J40: 26 | K40: 1999-10-14 | L40: USA | M40: 175 | N40: 128046 | P40: 4 | Q40: 247 | BD40: https://www.fotmob.com/players/924483/anthony-fontana
...

Sheet Equipos
A1: Club | B1: Conferencia | C1: Jugadores en plantilla | D1: Porteros | E1: Defensas | F1: Mediocampistas | G1: Delanteros | H1: Edad media | I1: Jugadores fuera de plantilla (jugaron 2026)
A2: Birmingham Legion FC | B2: Eastern | C2: =COUNTIFS(Jugadores!$C:$C,A2,Jugadores!$E:$E,"En plantilla") -> 23 | D2: =COUNTIFS(Jugadores!$C:$C,A2,Jugadores!$F:$F,"Portero") -> 2 | E2: =COUNTIFS(Jugadores!$C:$C,A2,Jugadores!$F:$F,"Defensa") -> 10 | F2: =COUNTIFS(Jugadores!$C:$C,A2,Jugadores!$F:$F,"Mediocampista") -> 7 | G2: =COUNTIFS(Jugadores!$C:$C,A2,Jugadores!$F:$F,"Delantero") -> 7 | H2: =AVERAGEIFS(Jugadores!$J:$J,Jugadores!$C:$C,A2,Jugadores!$E:$E,"En plantilla") -> 26.434783 | I2: =COUNTIFS(Jugadores!$C:$C,A2,Jugadores!$E:$E,"Fuera de plantilla actual") -> 3
A3: Brooklyn | B3: Eastern | C3: =COUNTIFS(Jugadores!$C:$C,A3,Jugadores!$E:$E,"En plantilla") -> 21 | D3: =COUNTIFS(Jugadores!$C:$C,A3,Jugadores!$F:$F,"Portero") -> 3 | E3: =COUNTIFS(Jugadores!$C:$C,A3,Jugadores!$F:$F,"Defensa") -> 7 | F3: =COUNTIFS(Jugadores!$C:$C,A3,Jugadores!$F:$F,"Mediocampista") -> 7 | G3: =COUNTIFS(Jugadores!$C:$C,A3,Jugadores!$F:$F,"Delantero") -> 7 | H3: =AVERAGEIFS(Jugadores!$J:$J,Jugadores!$C:$C,A3,Jugadores!$E:$E,"En plantilla") -> 26.380952 | I3: =COUNTIFS(Jugadores!$C:$C,A3,Jugadores!$E:$E,"Fuera de plantilla actual") -> 3
A4: Charleston Battery | B4: Eastern | C4: =COUNTIFS(Jugadores!$C:$C,A4,Jugadores!$E:$E,"En plantilla") -> 25 | D4: =COUNTIFS(Jugadores!$C:$C,A4,Jugadores!$F:$F,"Portero") -> 4 | E4: =COUNTIFS(Jugadores!$C:$C,A4,Jugadores!$F:$F,"Defensa") -> 7 | F4: =COUNTIFS(Jugadores!$C:$C,A4,Jugadores!$F:$F,"Mediocampista") -> 8 | G4: =COUNTIFS(Jugadores!$C:$C,A4,Jugadores!$F:$F,"Delantero") -> 7 | H4: =AVERAGEIFS(Jugadores!$J:$J,Jugadores!$C:$C,A4,Jugadores!$E:$E,"En plantilla") -> 25.52 | I4: =COUNTIFS(Jugadores!$C:$C,A4,Jugadores!$E:$E,"Fuera de plantilla actual") -> 1
A5: Detroit City FC | B5: Eastern | C5: =COUNTIFS(Jugadores!$C:$C,A5,Jugadores!$E:$E,"En plantilla") -> 27 | D5: =COUNTIFS(Jugadores!$C:$C,A5,Jugadores!$F:$F,"Portero") -> 3 | E5: =COUNTIFS(Jugadores!$C:$C,A5,Jugadores!$F:$F,"Defensa") -> 8 | F5: =COUNTIFS(Jugadores!$C:$C,A5,Jugadores!$F:$F,"Mediocampista") -> 6 | G5: =COUNTIFS(Jugadores!$C:$C,A5,Jugadores!$F:$F,"Delantero") -> 10 | H5: =AVERAGEIFS(Jugadores!$J:$J,Jugadores!$C:$C,A5,Jugadores!$E:$E,"En plantilla") -> 27.666667 | I5: =COUNTIFS(Jugadores!$C:$C,A5,Jugadores!$E:$E,"Fuera de plantilla actual") -> 0
A6: Hartford Athletic | B6: Eastern | C6: =COUNTIFS(Jugadores!$C:$C,A6,Jugadores!$E:$E,"En plantilla") -> 27 | D6: =COUNTIFS(Jugadores!$C:$C,A6,Jugadores!$F:$F,"Portero") -> 2 | E6: =COUNTIFS(Jugadores!$C:$C,A6,Jugadores!$F:$F,"Defensa") -> 6 | F6: =COUNTIFS(Jugadores!$C:$C,A6,Jugadores!$F:$F,"Mediocampista") -> 12 | G6: =COUNTIFS(Jugadores!$C:$C,A6,Jugadores!$F:$F,"Delantero") -> 8 | H6: =AVERAGEIFS(Jugadores!$J:$J,Jugadores!$C:$C,A6,Jugadores!$E:$E,"En plantilla") -> 24.888889 | I6: =COUNTIFS(Jugadores!$C:$C,A6,Jugadores!$E:$E,"Fuera de plantilla actual") -> 1
A7: Indy Eleven | B7: Eastern | C7: =COUNTIFS(Jugadores!$C:$C,A7,Jugadores!$E:$E,"En plantilla") -> 24 | D7: =COUNTIFS(Jugadores!$C:$C,A7,Jugadores!$F:$F,"Portero") -> 3 | E7: =COUNTIFS(Jugadores!$C:$C,A7,Jugadores!$F:$F,"Defensa") -> 12 | F7: =COUNTIFS(Jugadores!$C:$C,A7,Jugadores!$F:$F,"Mediocampista") -> 4 | G7: =COUNTIFS(Jugadores!$C:$C,A7,Jugadores!$F:$F,"Delantero") -> 7 | H7: =AVERAGEIFS(Jugadores!$J:$J,Jugadores!$C:$C,A7,Jugadores!$E:$E,"En plantilla") -> 26.958333 | I7: =COUNTIFS(Jugadores!$C:$C,A7,Jugadores!$E:$E,"Fuera de plantilla actual") -> 2
A8: Loudoun United FC | B8: Eastern | C8: =COUNTIFS(Jugadores!$C:$C,A8,Jugadores!$E:$E,"En plantilla") -> 25 | D8: =COUNTIFS(Jugadores!$C:$C,A8,Jugadores!$F:$F,"Portero") -> 3 | E8: =COUNTIFS(Jugadores!$C:$C,A8,Jugadores!$F:$F,"Defensa") -> 9 | F8: =COUNTIFS(Jugadores!$C:$C,A8,Jugadores!$F:$F,"Mediocampista") -> 10 | G8: =COUNTIFS(Jugadores!$C:$C,A8,Jugadores!$F:$F,"Delantero") -> 6 | H8: =AVERAGEIFS(Jugadores!$J:$J,Jugadores!$C:$C,A8,Jugadores!$E:$E,"En plantilla") -> 25.36 | I8: =COUNTIFS(Jugadores!$C:$C,A8,Jugadores!$E:$E,"Fuera de plantilla actual") -> 3
A9: Louisville City FC | B9: Eastern | C9: =COUNTIFS(Jugadores!$C:$C,A9,Jugadores!$E:$E,"En plantilla") -> 28 | D9: =COUNTIFS(Jugadores!$C:$C,A9,Jugadores!$F:$F,"Portero") -> 5 | E9: =COUNTIFS(Jugadores!$C:$C,A9,Jugadores!$F:$F,"Defensa") -> 5 | F9: =COUNTIFS(Jugadores!$C:$C,A9,Jugadores!$F:$F,"Mediocampista") -> 12 | G9: =COUNTIFS(Jugadores!$C:$C,A9,Jugadores!$F:$F,"Delantero") -> 6 | H9: =AVERAGEIFS(Jugadores!$J:$J,Jugadores!$C:$C,A9,Jugadores!$E:$E,"En plantilla") -> 26.107143 | I9: =COUNTIFS(Jugadores!$C:$C,A9,Jugadores!$E:$E,"Fuera de plantilla actual") -> 0
A10: Miami FC | B10: Eastern | C10: =COUNTIFS(Jugadores!$C:$C,A10,Jugadores!$E:$E,"En plantilla") -> 27 | D10: =COUNTIFS(Jugadores!$C:$C,A10,Jugadores!$F:$F,"Portero") -> 5 | E10: =COUNTIFS(Jugadores!$C:$C,A10,Jugadores!$F:$F,"Defensa") -> 13 | F10: =COUNTIFS(Jugadores!$C:$C,A10,Jugadores!$F:$F,"Mediocampista") -> 7 | G10: =COUNTIFS(Jugadores!$C:$C,A10,Jugadores!$F:$F,"Delantero") -> 6 | H10: =AVERAGEIFS(Jugadores!$J:$J,Jugadores!$C:$C,A10,Jugadores!$E:$E,"En plantilla") -> 24.814815 | I10: =COUNTIFS(Jugadores!$C:$C,A10,Jugadores!$E:$E,"Fuera de plantilla actual") -> 4
A11: Pittsburgh Riverhounds SC | B11: Eastern | C11: =COUNTIFS(Jugadores!$C:$C,A11,Jugadores!$E:$E,"En plantilla") -> 24 | D11: =COUNTIFS(Jugadores!$C:$C,A11,Jugadores!$F:$F,"Portero") -> 3 | E11: =COUNTIFS(Jugadores!$C:$C,A11,Jugadores!$F:$F,"Defensa") -> 7 | F11: =COUNTIFS(Jugadores!$C:$C,A11,Jugadores!$F:$F,"Mediocampista") -> 11 | G11: =COUNTIFS(Jugadores!$C:$C,A11,Jugadores!$F:$F,"Delantero") -> 4 | H11: =AVERAGEIFS(Jugadores!$J:$J,Jugadores!$C:$C,A11,Jugadores!$E:$E,"En plantilla") -> 25.458333 | I11: =COUNTIFS(Jugadores!$C:$C,A11,Jugadores!$E:$E,"Fuera de plantilla actual") -> 1
A12: Rhode Island FC | B12: Eastern | C12: =COUNTIFS(Jugadores!$C:$C,A12,Jugadores!$E:$E,"En plantilla") -> 27 | D12: =COUNTIFS(Jugadores!$C:$C,A12,Jugadores!$F:$F,"Portero") -> 3 | E12: =COUNTIFS(Jugadores!$C:$C,A12,Jugadores!$F:$F,"Defensa") -> 7 | F12: =COUNTIFS(Jugadores!$C:$C,A12,Jugadores!$F:$F,"Mediocampista") -> 10 | G12: =COUNTIFS(Jugadores!$C:$C,A12,Jugadores!$F:$F,"Delantero") -> 9 | H12: =AVERAGEIFS(Jugadores!$J:$J,Jugadores!$C:$C,A12,Jugadores!$E:$E,"En plantilla") -> 24.555556 | I12: =COUNTIFS(Jugadores!$C:$C,A12,Jugadores!$E:$E,"Fuera de plantilla actual") -> 2
A13: Sporting JAX | B13: Eastern | C13: =COUNTIFS(Jugadores!$C:$C,A13,Jugadores!$E:$E,"En plantilla") -> 30 | D13: =COUNTIFS(Jugadores!$C:$C,A13,Jugadores!$F:$F,"Portero") -> 3 | E13: =COUNTIFS(Jugadores!$C:$C,A13,Jugadores!$F:$F,"Defensa") -> 11 | F13: =COUNTIFS(Jugadores!$C:$C,A13,Jugadores!$F:$F,"Mediocampista") -> 12 | G13: =COUNTIFS(Jugadores!$C:$C,A13,Jugadores!$F:$F,"Delantero") -> 6 | H13: =AVERAGEIFS(Jugadores!$J:$J,Jugadores!$C:$C,A13,Jugadores!$E:$E,"En plantilla") -> 26.533333 | I13: =COUNTIFS(Jugadores!$C:$C,A13,Jugadores!$E:$E,"Fuera de plantilla actual") -> 2
... A26: San Antonio FC | B26: Western | C26: =COUNTIFS(Jugadores!$C:$C,A26,Jugadores!$E:$E,"En plantilla") -> 28 | D26: =COUNTIFS(Jugadores!$C:$C,A26,Jugadores!$F:$F,"Portero") -> 4 | E26: =COUNTIFS(Jugadores!$C:$C,A26,Jugadores!$F:$F,"Defensa") -> 10 | F26: =COUNTIFS(Jugadores!$C:$C,A26,Jugadores!$F:$F,"Mediocampista") -> 7 | G26: =COUNTIFS(Jugadores!$C:$C,A26,Jugadores!$F:$F,"Delantero") -> 9 | H26: =AVERAGEIFS(Jugadores!$J:$J,Jugadores!$C:$C,A26,Jugadores!$E:$E,"En plantilla") -> 26.428571 | I26: =COUNTIFS(Jugadores!$C:$C,A26,Jugadores!$E:$E,"Fuera de plantilla actual") -> 2
A27: TOTAL | C27: =SUM(C2:C26) -> 669 | D27: =SUM(D2:D26) -> 85 | E27: =SUM(E2:E26) -> 235 | F27: =SUM(F2:F26) -> 220 | G27: =SUM(G2:G26) -> 185 | H27: =AVERAGEIFS(Jugadores!$J:$J,Jugadores!$E:$E,"En plantilla") -> 25.508221 | I27: =SUM(I2:I26) -> 56

Sheet Notas
A1: Campo | B1: Detalle
A2: Fuente | B2: FotMob — USL Championship 2026 (liga 8972, temporada 30301). Plantillas: fotmob.com/teams/[id]/squad. Estadísticas: data.fotmob.com/stats/8972/season/30301/*.json
A3: Fecha de extracción | B3: 30 sep 2026 (tras ~26 jornadas de temporada regular)
A4: Cobertura | B4: 669 jugadores en plantillas actuales de los 25 clubes + 56 que jugaron en 2026 pero ya no figuran en ninguna plantilla (cedidos/traspasados/liberados). Entrenadores excluidos.
A5: Métricas /90 | B5: FotMob solo publica las métricas por 90 min a partir de un mínimo de minutos; una celda vacía significa "sin dato / por debajo del umbral", no cero.
A6: Valor est. FotMob (€) | B6: Estimación algorítmica de FotMob, no valor de mercado real ni salario. Útil solo como referencia relativa.
A7: Lexington SC | B7: LSC aparece incluido como referencia de comparación; filtrar Club ≠ "Lexington SC" para ver objetivos externos.
A8: Rating FotMob / MVP partido | B8: Rating medio de temporada; MVP = veces nombrado jugador del partido.
A9: Estado del contrato | B9: No disponible en FotMob — pendiente de otra fuente si se usa como criterio.
A10: Próximo paso | B10: Añadir criterios de scouting (posición, edad, minutos mínimos, métricas clave) y construir ranking/percentiles por posición.
